<?xml version="1.0"?>
<robot name="ur3" xmlns:xacro="http://ros.org/wiki/xacro">

    <xacro:macro name="cylinder_inertial" params="radius length mass">
      <inertial>
        <mass value="${mass}" />
        <inertia ixx="${0.0833333 * mass * (3 * radius * radius + length * length)}" ixy="0.0" ixz="0.0"
          iyy="${0.0833333 * mass * (3 * radius * radius + length * length)}" iyz="0.0"
          izz="${0.5 * mass * radius * radius}" />
      </inertial>
    </xacro:macro>

    <link name="base_link" >
      <visual>
        <geometry>
          <mesh filename="file:///home/wymt/c++/ROS/urdf/myUR3/base.dae"/>
        </geometry>
        <material name="grey">
          <color rgba="0.7 0.7 0.7 1"/>
        </material>
      </visual>
      <collision>
        <geometry>
          <mesh filename="file:///home/wymt/c++/ROS/urdf/myUR3/base.stl"/>
        </geometry>
    </collision>
    <origin xyz="0.0 0.0 0.0" rpy="0 0 0" />
      <xacro:cylinder_inertial radius="0.075" length="0.038" mass="2.0">
    </xacro:cylinder_inertial>
    </link>

    <link name="shoulder_link">
      <visual>
        <geometry>
          <mesh filename="file:///home/wymt/c++/ROS/urdf/myUR3/shoulder.dae"/>
        </geometry>
        <material name="blue">
          <color rgba="0 0 0.7 1"/>
        </material>
      </visual>
      <collision>
        <geometry>
           <mesh filename="file:///home/wymt/c++/ROS/urdf/myUR3//shoulder.stl"/>
        </geometry>
      </collision>
      <origin xyz="0.0 0.0 0.0" rpy="0 0 0" />
      <xacro:cylinder_inertial radius="0.075" length="0.178" mass="2.0">
      </xacro:cylinder_inertial>
    </link>

    <link name="upper_arm_link">
      <visual>
        <geometry>
          <mesh filename="file:///home/wymt/c++/ROS/urdf/myUR3/upperarm.dae"/>
        </geometry>
        <material name="lgreen">
          <color rgba="0 0.7 0.3 1"/>
        </material>
      </visual>
      <collision>
        <geometry>
          <mesh filename="file:///home/wymt/c++/ROS/urdf/myUR3/upperarm.stl"/>
        </geometry>
      </collision>
      <origin xyz="0.0 0.0 0.12" rpy="0 0 0" />
      <xacro:cylinder_inertial radius="0.075" length="0.24" mass="3.42">
      </xacro:cylinder_inertial>
    </link>

    <link name="forearm_link">
      <visual>
         <geometry>
          <mesh filename="file:///home/wymt/c++/ROS/urdf/myUR3/forearm.dae"/>
        </geometry>
        <material name="yellow">
          <color rgba="0.7 0.7 0 1"/>
        </material>
      </visual>
      <collision>
        <geometry>
         <mesh filename="file:///home/wymt/c++/ROS/urdf/myUR3/forearm.stl"/>
        </geometry>
      </collision>
      <origin xyz="0.0 0.0 0.105" rpy="0 0 0"/>
      <xacro:cylinder_inertial radius="0.075" length="0.21" mass="1.26">
      </xacro:cylinder_inertial>
    </link>

    <link name="wrist_1_link">
      <visual>
        <geometry>
          <mesh filename="file:///home/wymt/c++/ROS/urdf/myUR3/wrist1.dae"/>
        </geometry>
        <material name="purple">
          <color rgba="0.7 0 0.7 1"/>
        </material>
      </visual>
      <collision>
        <geometry>
          <mesh filename="file:///home/wymt/c++/ROS/urdf/myUR3/wrist1.stl"/>
        </geometry>
      </collision>
      <origin xyz="0.0 0.0 0.0" rpy="0 0 0" />
      <xacro:cylinder_inertial radius="0.075" length="0.12" mass="0.8">
      </xacro:cylinder_inertial>
    </link>

    <link name="wrist_2_link">
      <visual>
        <geometry>
          <mesh filename="file:///home/wymt/c++/ROS/urdf/myUR3/wrist2.dae"/>
        </geometry>
        <material name="orange">
          <color rgba="0.7 0.35 0 1"/>
        </material>
      </visual>
      <collision>
        <geometry>
          <mesh filename="file:///home/wymt/c++/ROS/urdf/myUR3/wrist2.stl"/>
        </geometry>
      </collision>
      <origin xyz="0.0 0.0 0.0" rpy="0 0 0" />
      <xacro:cylinder_inertial radius="0.075" length="0.12" mass="0.8">
      </xacro:cylinder_inertial>
    </link>

    <link name="wrist_3_link">
      <visual>
        <geometry>
          <mesh filename="file:///home/wymt/c++/ROS/urdf/myUR3/wrist3.dae"/>
        </geometry>
        <material name="lbule">
          <color rgba="0 0.25 0.5 1"/>
        </material>
      </visual>
      <collision>
        <geometry>
          <mesh filename="file:///home/wymt/c++/ROS/urdf/myUR3/wrist3.stl"/>
        </geometry>
      </collision>
      <origin xyz="0.0 0.0 0.0" rpy="0 0 0" />
      <xacro:cylinder_inertial radius="0.075" length="0.12" mass="0.35">
      </xacro:cylinder_inertial>
    </link>

    <link name="ee_link">
      <collision>
        <geometry>
          <box size="0.01 0.01 0.01"/>
        </geometry>
        <origin rpy="0 0 0" xyz="-0.01 0 0"/>
      </collision>
    </link>

    <link name="camera_link">
        <collision>
          <origin xyz="0 0 0" rpy="0 0 0"/>
          <geometry>
        <box size="0.05 0.05 0.05"/>
          </geometry>
        </collision>

        <visual>
          <origin xyz="0 0 0" rpy="0 0 0"/>
          <geometry>
        <box size="0.05 0.05 0.05"/>
          </geometry>
          <material name="red">
            <color rgba="0.7 0 0 1"/>
          </material>
        </visual>

        <inertial>
          <mass value="1e-5" />
          <origin xyz="0 0 0" rpy="0 0 0"/>
          <inertia ixx="1e-6" ixy="0" ixz="0" iyy="1e-6" iyz="0" izz="1e-6" />
        </inertial>
    </link>

    <link name="base"/>
    <link name="tool"/>
    <link name="world"/>

    <joint name="shoulder_pan_joint" type="revolute">
      <parent link="base_link" />
      <child link = "shoulder_link" />
      <origin xyz="0.0 0.0 0.1519" rpy="0.0 0.0 0.0" />
      <axis xyz="0 0 1" />
      <limit lower="-6.28" upper="6.28" effort="330.0" velocity="2.16"/>
      <dynamics damping="0.0" friction="0.0"/>
    </joint>

    <joint name="shoulder_lift_joint" type="revolute">
      <parent link="shoulder_link" />
      <child link = "upper_arm_link" />
      <origin xyz="0.0 0.1198 0.0" rpy="0.0 1.57 0.0" />
      <axis xyz="0 1 0" />
      <limit lower="-6.28" upper="6.28" effort="330.0" velocity="2.16"/>
      <dynamics damping="0.0" friction="0.0"/>
    </joint>

    <joint name="elbow_joint" type="revolute">
      <parent link="upper_arm_link" />
      <child link = "forearm_link" />
      <origin xyz="0.0 -0.0925 0.24365" rpy="0.0 0.0 0.0" />
      <axis xyz="0 1 0" />
      <limit lower="-3.14" upper="3.14" effort="150.0" velocity="3.15"/>
      <dynamics damping="0.0" friction="0.0"/>
    </joint>

    <joint name="wrist_1_joint" type="revolute">
      <parent link="forearm_link" />
      <child link = "wrist_1_link" />
      <origin xyz="0.0 0.0 0.21325" rpy="0.0 1.57 0.0" />
      <axis xyz="0 1 0" />
      <limit lower="-6.28" upper="6.28" effort="54.0" velocity="3.2"/>
      <dynamics damping="0.0" friction="0.0"/>
    </joint>

    <joint name="wrist_2_joint" type="revolute">
      <parent link="wrist_1_link" />
      <child link = "wrist_2_link" />
      <origin xyz="0.0 0.08505 0.0" rpy="0.0 0.0 0.0" />
      <axis xyz="0 0 1" />
      <limit lower="-6.28" upper="6.28" effort="54.0" velocity="3.2"/>
      <dynamics damping="0.0" friction="0.0"/>
    </joint>

    <joint name="wrist_3_joint" type="revolute">
      <parent link="wrist_2_link" />
      <child link = "wrist_3_link" />
      <origin xyz="0.0 0.0 0.08535" rpy="0.0 0.0 0.0" />
      <axis xyz="0 1 0" />
      <limit lower="-1.57" upper="1.57" effort="54.0" velocity="3.2"/>
      <dynamics damping="0.0" friction="0.0"/>
    </joint>

    <joint name="ee_fixed_joint" type="fixed">
      <parent link="wrist_3_link" />
      <child link = "ee_link" />
      <origin xyz="0.0 0.0819 0.0" rpy="0.0 0.0 1.57" />
    </joint>

    <joint name="base_link-base_fixed_joint" type="fixed">
      <origin xyz="0 0 0" rpy="0 0 -3.14"/>
      <parent link="base_link"/>
      <child link="base"/>
    </joint>

    <joint name="wrist_3_link-tool0_fixed_joint" type="fixed">
      <origin xyz="0 0.0819 0" rpy="-1.57 0 0"/>
      <parent link="wrist_3_link"/>
      <child link="tool"/>
    </joint>

    <joint name="world_joint" type="fixed">
      <parent link="world" />
      <child link = "base_link" />
      <origin xyz="0.0 0.0 0.0" rpy="0.0 0.0 0.0" />
    </joint>

    <joint name="camera_joint" type="fixed">
      <axis xyz="0 1 0" />
      <parent link="ee_link"/>
      <child link="camera_link"/>
      <origin xyz="0.03 0 0" rpy="3.14 0 0"/>
    </joint>


    <transmission name="shoulder_pan_trans">
      <type>transmission_interface/SimpleTransmission</type>
      <joint name="shoulder_pan_joint">
        <hardwareInterface>hardware_interface/PositionJointInterface</hardwareInterface>
      </joint>
      <actuator name="shoulder_pan_motor">
        <mechanicalReduction>1</mechanicalReduction>
      </actuator>
    </transmission>

    <transmission name="shoulder_lift_trans">
      <type>transmission_interface/SimpleTransmission</type>
      <joint name="shoulder_lift_joint">
        <hardwareInterface>hardware_interface/PositionJointInterface</hardwareInterface>
      </joint>
      <actuator name="shoulder_lift_motor">
        <mechanicalReduction>1</mechanicalReduction>
      </actuator>
    </transmission>

    <transmission name="elbow_trans">
      <type>transmission_interface/SimpleTransmission</type>
      <joint name="elbow_joint">
        <hardwareInterface>hardware_interface/PositionJointInterface</hardwareInterface>
      </joint>
      <actuator name="elbow_motor">
        <mechanicalReduction>1</mechanicalReduction>
      </actuator>
    </transmission>

    <transmission name="wrist_1_trans">
      <type>transmission_interface/SimpleTransmission</type>
      <joint name="wrist_1_joint">
        <hardwareInterface>hardware_interface/PositionJointInterface</hardwareInterface>
      </joint>
      <actuator name="wrist_1_motor">
        <mechanicalReduction>1</mechanicalReduction>
      </actuator>
    </transmission>

    <transmission name="wrist_2_trans">
      <type>transmission_interface/SimpleTransmission</type>
      <joint name="wrist_2_joint">
        <hardwareInterface>hardware_interface/PositionJointInterface</hardwareInterface>
      </joint>
      <actuator name="wrist_2_motor">
        <mechanicalReduction>1</mechanicalReduction>
      </actuator>
    </transmission>

    <transmission name="wrist_3_trans">
      <type>transmission_interface/SimpleTransmission</type>
      <joint name="wrist_3_joint">
        <hardwareInterface>hardware_interface/PositionJointInterface</hardwareInterface>
      </joint>
      <actuator name="wrist_3_motor">
        <mechanicalReduction>1</mechanicalReduction>
      </actuator>
    </transmission>

    <!-- camera -->
    <gazebo reference="camera_link">
        <sensor type="camera" name="camera1">
          <update_rate>30.0</update_rate>
          <camera name="head">
            <horizontal_fov>1.3962634</horizontal_fov>
            <image>
              <width>800</width>
              <height>800</height>
              <format>R8G8B8</format>
            </image>
            <clip>
              <near>0.02</near>
              <far>300</far>
            </clip>
            <noise>
              <type>gaussian</type>
              <!-- Noise is sampled independently per pixel on each frame.
                   That pixel's noise value is added to each of its color
                   channels, which at that point lie in the range [0,1]. -->
              <mean>0.0</mean>
              <stddev>0.007</stddev>
            </noise>
          </camera>
          <plugin name="camera_controller" filename="libgazebo_ros_camera.so">
            <alwaysOn>true</alwaysOn>
            <updateRate>0.0</updateRate>
            <cameraName>rrbot/camera1</cameraName>
            <imageTopicName>image_raw</imageTopicName>
            <cameraInfoTopicName>camera_info</cameraInfoTopicName>
            <frameName>camera_link</frameName>
            <hackBaseline>0.07</hackBaseline>
            <distortionK1>0.0</distortionK1>
            <distortionK2>0.0</distortionK2>
            <distortionK3>0.0</distortionK3>
            <distortionT1>0.0</distortionT1>
            <distortionT2>0.0</distortionT2>
          </plugin>
        </sensor>
    </gazebo>

    <gazebo>
      <plugin name="gazebo_ros_control" filename="libgazebo_ros_control.so">
      </plugin>
    </gazebo>

</robot>
