<?xml version="1.0" encoding="UTF-8"?>
<robot name="grasper" xmlns:xacro="http://ros.org/wiki/xacro">

  <material name="blue">
    <color rgba="0 0 0.8 1"/>
  </material>
  <material name="black">
    <color rgba="0 0 0 1"/>
  </material>
  <material name="white">
    <color rgba="1 1 1 1"/>
  </material>

  <xacro:macro name="default_inertial" params="mass">
    <inertial>
      <mass value="${mass}" />
      <inertia ixx="1.0" ixy="0.0" ixz="0.0" iyy="1.0" iyz="0.0" izz="1.0" />
    </inertial>
  </xacro:macro>

  <link name="base_link">
    <visual>
      <geometry>
        <cylinder length="0.6" radius="0.1"/>
      </geometry>
      <origin rpy="1.57 0 0" xyz="0 0.3 0"/>
      <material name="blue"/>
    </visual>
    <collision>
      <geometry>
        <cylinder length="0.6" radius="0.1"/>
      </geometry>
    </collision>
    <xacro:default_inertial mass="10"/>
  </link>

  <link name="link1">
    <visual>
      <geometry>
        <cylinder length="0.6" radius="0.1"/>
      </geometry>
      <origin rpy="1.57 0 0" xyz="0 0.3 0"/>
      <material name="blue"/>
    </visual>
    <collision>
      <geometry>
        <cylinder length="0.6" radius="0.1"/>
      </geometry>
    </collision>
    <xacro:default_inertial mass="10"/>
  </link>

  <link name="link2">
    <visual>
      <geometry>
        <cylinder length="0.6" radius="0.1"/>
      </geometry>
      <origin rpy="1.57 0 0" xyz="0 0.3 0"/>
      <material name="blue"/>
    </visual>
    <collision>
      <geometry>
        <cylinder length="0.6" radius="0.1"/>
      </geometry>
    </collision>
    <xacro:default_inertial mass="10"/>
  </link>

  <link name="hand_base">
    <visual>
    <geometry>
      <cylinder length="0.1" radius="0.3"/>
    </geometry>
      <origin rpy="1.57 0 0" xyz="0 0.05 0"/>
      <material name="black"/>
    </visual>
    <collision>
      <geometry>
        <cylinder length="0.1" radius="0.3"/>
      </geometry>
    </collision>
    <xacro:default_inertial mass="20"/>
  </link>

  <link name="finger1">
    <visual>
      <geometry>
        <cylinder length="0.2" radius="0.05"/>
      </geometry>
        <origin rpy="1.57 0 0" xyz="0 0.2 0"/>
        <material name="white"/>
    </visual>
    <collision>
      <geometry>
        <cylinder length="0.2" radius="0.5"/>
      </geometry>
    </collision>
    <xacro:default_inertial mass="2"/>
  </link>

  <link name="finger2">
      <visual>
      <geometry>
        <cylinder length="0.2" radius="0.05"/>
      </geometry>
        <origin rpy="1.57 0 0" xyz="0 0.2 0"/>
        <material name="white"/>
    </visual>
    <collision>
      <geometry>
        <cylinder length="0.2" radius="0.5"/>
      </geometry>
    </collision>
    <xacro:default_inertial mass="2"/>
  </link>

  <joint name="joint1" type="continuous">
    <parent link="base_link"/>
    <child link="link1"/>
    <origin xyz="0 0.6 0"/>
  </joint>

  <joint name="joint2" type="continuous">
    <parent link="link1"/>
    <child link="link2"/>
    <origin xyz="0 0.6 0"/>
  </joint>

  <joint name="joint3" type="revolute">
    <axis xyz="0 1 0"/>
    <limit effort="2000.0" lower="0.0" upper="3.1415" velocity="0.5"/>
    <parent link="link2"/>
    <child link="hand_base"/>
    <origin xyz="0 0.6 0"/>
  </joint>

  <joint name="joint4" type="prismatic">
    <parent link="hand_base"/>
    <child link="finger1"/>
    <origin xyz="-0.3 0 0"/>
    <limit effort="1000.0" lower="0" upper="0.15" velocity="0.5"/>
  </joint>

  <joint name="joint5" type="prismatic">
    <parent link="hand_base"/>
    <child link="finger2"/>
    <origin xyz="0.3 0 0"/>
    <limit effort="1000.0" lower="-0.15" upper="0" velocity="0.5"/>
  </joint>

  <gazebo>
    <plugin name="gazebo_ros_control" filename="libgazebo_ros_control.so">
      <robotNamespace>/</robotNamespace>
    </plugin>
  </gazebo>

</robot>
